Workbook
Name Footfall: 'Interactive Dashborad '!$K$11:$M$19
Name Quarters: 'Interactive Dashborad '!$M$6
Name Slicer_Month: #N/A
Name Slicer_Products: #N/A
Name week: 'Combined Pivot '!$A$1:$B$9

Sheet Dashboard
L2: Products | M2: Price | N2: Sales Percentage
L3: =Pivot!J4 -> Latte | M3: =Pivot!K4 -> 38.7 | N3: =Pivot!L4 -> 0.24140967
L4: =Pivot!J5 -> Americano with Milk | M4: =Pivot!K5 -> 33.8 | N4: =Pivot!L5 -> 0.21890994
L5: =Pivot!J6 -> Cappuccino | M5: =Pivot!K6 -> 38.7 | N5: =Pivot!L6 -> 0.15623229
L6: =Pivot!J7 -> Americano | M6: =Pivot!K7 -> 28.9 | N6: =Pivot!L7 -> 0.13048648
G7: Quarter | H7: Sum of Sales | L7: =Pivot!J8 -> Hot Chocolate | M7: =Pivot!K8 -> 38.7 | N7: =Pivot!L8 -> 0.088125451
G8: =Pivot!A18 -> 4th | H8: =GETPIVOTDATA("SALES",Pivot!$A$17,"QUARTERS","4th") -> 30719.44 | L8: =Pivot!J9 -> Cocoa | M8: =Pivot!K9 -> 38.7 | N8: =Pivot!L9 -> 0.07518012
G9: =Pivot!A19 -> 1st | H9: =Pivot!B19 -> 28132.66 | L9: =Pivot!J10 -> Cortado | M9: =Pivot!K10 -> 28.9 | N9: =Pivot!L10 -> 0.065275551
G10: =Pivot!A20 -> 3rd | H10: =Pivot!B20 -> 24518.42 | L10: =Pivot!J11 -> Espresso | M10: =Pivot!K11 -> 24 | N10: =Pivot!L11 -> 0.024380503
G11: =Pivot!A21 -> 2nd | H11: =Pivot!B21 -> 23542.74

Sheet Interactive Dashborad 
M4: Quarters | N4: Sales
M5: ='Pivot 2'!D18 -> 1 | N5: ='Pivot 2'!E18 -> 36650.98
M6: ='Pivot 2'!D19 -> 4 | N6: ='Pivot 2'!E19 -> 30719.44
M7: ='Pivot 2'!D20 -> 3 | N7: ='Pivot 2'!E20 -> 24518.42
M8: ='Pivot 2'!D21 -> 2 | N8: ='Pivot 2'!E21 -> 23542.74
K11: Products | L11: Footfall | M11: Percentage | O11: Product | P11: Price | Q11: Sales Percentage
K12: =Pivot!D18 -> Americano with Milk | L12: =Pivot!E18 -> 824 | M12: =Pivot!F18 -> 0.22662266 | O12: =Pivot!J4 -> Latte | P12: =Pivot!K4 -> 38.7 | Q12: =Pivot!L4 -> 0.24140967
K13: =Pivot!D19 -> Latte | L13: =Pivot!E19 -> 782 | M13: =Pivot!F19 -> 0.21507151 | O13: =Pivot!J5 -> Americano with Milk | P13: =Pivot!K5 -> 33.8 | Q13: =Pivot!L5 -> 0.21890994
K14: =Pivot!D20 -> Americano | L14: =Pivot!E20 -> 578 | M14: =Pivot!F20 -> 0.1589659 | O14: =Pivot!J6 -> Cappuccino | P14: =Pivot!K6 -> 38.7 | Q14: =Pivot!L6 -> 0.15623229
K15: =Pivot!D21 -> Cappuccino | L15: =Pivot!E21 -> 501 | M15: =Pivot!F21 -> 0.13778878 | O15: =Pivot!J7 -> Americano | P15: =Pivot!K7 -> 28.9 | Q15: =Pivot!L7 -> 0.13048648
K16: =Pivot!D22 -> Cortado | L16: =Pivot!E22 -> 292 | M16: =Pivot!F22 -> 0.080308031 | O16: =Pivot!J8 -> Hot Chocolate | P16: =Pivot!K8 -> 38.7 | Q16: =Pivot!L8 -> 0.088125451
K17: =Pivot!D23 -> Hot Chocolate | L17: =Pivot!E23 -> 282 | M17: =Pivot!F23 -> 0.077557756 | O17: =Pivot!J9 -> Cocoa | P17: =Pivot!K9 -> 38.7 | Q17: =Pivot!L9 -> 0.07518012
K18: =Pivot!D24 -> Cocoa | L18: =Pivot!E24 -> 243 | M18: =Pivot!F24 -> 0.066831683 | O18: =Pivot!J10 -> Cortado | P18: =Pivot!K10 -> 28.9 | Q18: =Pivot!L10 -> 0.065275551
K19: =Pivot!D25 -> Espresso | L19: =Pivot!E25 -> 134 | M19: =Pivot!F25 -> 0.036853685 | O19: =Pivot!J11 -> Espresso | P19: =Pivot!K11 -> 24 | Q19: =Pivot!L11 -> 0.024380503

Sheet Combined Pivot 
A1: Row Labels | B1: Sum of money | D1: Row Labels | E1: Count of Cash_type | G1: Row Labels | H1: Sum of money | J1: Row Labels | K1: Sum of money
A2: Tuesday | B2: 16440.92 | D2: Sunday | E2: 389 | G2: January | H2: 5732.66 | J2: Latte | K2: 25471.86
A3: Monday | B3: 16156.96 | D3: Monday | E3: 504 | G3: July | H3: 6287 | J3: Americano with Milk | K3: 22539.54
A4: Friday | B4: 15120.98 | D4: Tuesday | E4: 515 | G4: June | H4: 6530.48 | J4: Cappuccino | K4: 16455.8
A5: Thursday | B5: 15044.12 | D5: Wednesday | E5: 461 | G5: April | H5: 6546.66 | J5: Americano | K5: 12608.6
A6: Wednesday | B6: 14600.92 | D6: Thursday | E6: 474 | G6: August | H6: 6736.58 | J6: Hot Chocolate | K6: 9135.42
A7: Saturday | B7: 13148.14 | D7: Friday | E7: 474 | G7: November | H7: 7483.96 | J7: Cocoa | K7: 7576.46
A8: Sunday | B8: 12443.88 | D8: Saturday | E8: 413 | G8: December | H8: 7537.76 | J8: Cortado | K8: 6468.56
A9: Grand Total | B9: 102955.92 | D9: Grand Total | E9: 3230 | G9: May | H9: 8161.9 | J9: Espresso | K9: 2699.68
G10: September | H10: 8560.8 | J10: Grand Total | K10: 102955.92
A11: Row Labels | B11: Sum of money | D11: Row Labels | E11: Count of Cash_type | G11: February | H11: 11643.6
A12: Tuesday | B12: 16440.92 | D12: Card | E12: 3144 | G12: October | H12: 12073.34
A13: Americano | B13: 1807.14 | D13: Cash | E13: 86 | G13: March | H13: 15661.18
A14: Americano with Milk | B14: 3644.04 | D14: Grand Total | E14: 3230 | G14: Grand Total | H14: 102955.92
A15: Cappuccino | B15: 2196.02
A16: Cocoa | B16: 1717.76 | D16: Row Labels | E16: Sum of money
A17: Cortado | B17: 1113.46 | D17: 2024 | E17: 76968.68
A18: Espresso | B18: 327.16 | D18: 2025 | E18: 25987.24
A19: Hot Chocolate | B19: 1662.92 | D19: Grand Total | E19: 102955.92
A20: Latte | B20: 3972.42
A21: Monday | B21: 16156.96 | D21: Row Labels | E21: Sum of money
A22: Americano | B22: 2098.78 | D22: ANON-0000-0000-0012 | E22: 3143.74
A23: Americano with Milk | B23: 3779.76 | D23: ANON-0000-0000-0009 | E23: 2278.34
A24: Cappuccino | B24: 2383.64 | D24: ANON-0000-0000-0141 | E24: 2252.14
A25: Cocoa | B25: 1029.2 | D25: ANON-0000-0000-0276 | E25: 1930.46
A26: Cortado | B26: 816.64 | D26: ANON-0000-0000-1163 | E26: 1658.1
A27: Espresso | B27: 259.62 | D27: ANON-0000-0000-0507 | E27: 1549.92
A28: Hot Chocolate | B28: 1140.4 | D28: ANON-0000-0000-0097 | E28: 1333.36
A29: Latte | B29: 4648.92 | D29: ANON-0000-0000-0040 | E29: 1258.4
A30: Friday | B30: 15120.98 | D30: ANON-0000-0000-0570 | E30: 1061.04
A31: Americano | B31: 2194.48 | D31: ANON-0000-0000-0206 | E31: 812.68
A32: Americano with Milk | B32: 2898.3 | D32: ANON-0000-0000-1191 | E32: 715.2
A33: Cappuccino | B33: 2094.64 | D33: ANON-0000-0000-0003 | E33: 701.92
... A75: Grand Total | B75: 102955.92 | D75: ANON-0000-0000-0877 | E75: 245.42
D76: ANON-0000-0000-0731 | E76: 245.42
D77: ANON-0000-0000-0050 | E77: 235.12
D78: ANON-0000-0000-0164 | E78: 234.64
D79: ANON-0000-0000-0017 | E79: 232.2
D80: ANON-0000-0000-0304 | E80: 232.18
D81: ANON-0000-0000-0225 | E81: 228.26
...

Sheet  Dashboard 
I3: Year | J3: Total Sales | K3: Percentage
I4: ='Combined Pivot '!D17 -> 2024 | J4: ='Combined Pivot '!E17 -> 76968.68 | K4: =SUM(J4)/SUM($J$4:$J$5) -> 0.74758868 | M4: Products | N4: Sales by Price | O4: Percentage
I5: ='Combined Pivot '!D18 -> 2025 | J5: ='Combined Pivot '!E18 -> 25987.24 | K5: =SUM(J5)/SUM($J$4:$J$5) -> 0.25241132 | M5: ='Combined Pivot '!J2 -> Latte | N5: ='Combined Pivot '!K2 -> 25471.86 | O5: =SUM(N5)/SUM($N$5:$N$12) -> 0.24740549
I6: Total Sales | J6: ='Combined Pivot '!E19 -> 102955.92 | K6: =SUM(K4:K5) -> 1 | M6: ='Combined Pivot '!J3 -> Americano with Milk | N6: ='Combined Pivot '!K3 -> 22539.54 | O6: =SUM(N6)/SUM($N$5:$N$12) -> 0.21892418
M7: ='Combined Pivot '!J4 -> Cappuccino | N7: ='Combined Pivot '!K4 -> 16455.8 | O7: =SUM(N7)/SUM($N$5:$N$12) -> 0.15983345
M8: ='Combined Pivot '!J5 -> Americano | N8: ='Combined Pivot '!K5 -> 12608.6 | O8: =SUM(N8)/SUM($N$5:$N$12) -> 0.122466
I9: Day | J9: Best selling Product | K9: Amouunt Sold | M9: ='Combined Pivot '!J6 -> Hot Chocolate | N9: ='Combined Pivot '!K6 -> 9135.42 | O9: =SUM(N9)/SUM($N$5:$N$12) -> 0.088731372
I10: ='Combined Pivot '!A12 -> Tuesday | J10: ='Combined Pivot '!A20 -> Latte | K10: =GETPIVOTDATA("money",'Combined Pivot '!$A$11,"Day","Tuesday","coffee_name","Latte") -> 3972.42 | M10: ='Combined Pivot '!J7 -> Cocoa | N10: ='Combined Pivot '!K7 -> 7576.46 | O10: =SUM(N10)/SUM($N$5:$N$12) -> 0.073589357
I11: ='Combined Pivot '!A21 -> Monday | J11: ='Combined Pivot '!A29 -> Latte | K11: =GETPIVOTDATA("money",'Combined Pivot '!$A$11,"Day","Monday","coffee_name","Latte") -> 4648.92 | M11: ='Combined Pivot '!J8 -> Cortado | N11: ='Combined Pivot '!K8 -> 6468.56 | O11: =SUM(N11)/SUM($N$5:$N$12) -> 0.062828442
I12: ='Combined Pivot '!A30 -> Friday | J12: ='Combined Pivot '!A38 -> Latte | K12: =GETPIVOTDATA("money",'Combined Pivot '!$A$11,"Day","Friday","coffee_name","Latte") -> 3538.84 | M12: ='Combined Pivot '!J9 -> Espresso | N12: ='Combined Pivot '!K9 -> 2699.68 | O12: =SUM(N12)/SUM($N$5:$N$12) -> 0.026221707
I13: ='Combined Pivot '!A39 -> Thursday | J13: ='Combined Pivot '!A47 -> Latte | K13: =GETPIVOTDATA("money",'Combined Pivot '!$A$11,"Day","Thursday","coffee_name","Latte") -> 3789.02
I14: ='Combined Pivot '!A48 -> Wednesday | J14: ='Combined Pivot '!A56 -> Latte | K14: =GETPIVOTDATA("money",'Combined Pivot '!$A$11,"Day","Wednesday","coffee_name","Latte") -> 3615.14
I15: ='Combined Pivot '!A57 -> Saturday | J15: ='Combined Pivot '!A59 -> Americano with Milk | K15: =GETPIVOTDATA("money",'Combined Pivot '!$A$11,"Day","Saturday","coffee_name","Americano with Milk") -> 3360.54 | M15: Products | N15: Gross Sales | O15: Price
I16: ='Combined Pivot '!A66 -> Sunday | J16: ='Combined Pivot '!A74 -> Latte | K16: =GETPIVOTDATA("money",'Combined Pivot '!$A$11,"Day","Sunday","coffee_name","Latte") -> 2951.56 | M16: ='Combined Pivot '!J2 -> Latte | N16: ='Combined Pivot '!K2 -> 25471.86 | O16: =index_1!E21 -> 38.7
M17: ='Combined Pivot '!J3 -> Americano with Milk | N17: ='Combined Pivot '!K3 -> 22539.54 | O17: =index_1!E12 -> 33.8
M18: ='Combined Pivot '!J4 -> Cappuccino | N18: ='Combined Pivot '!K4 -> 16455.8 | O18: =index_1!E55 -> 38.7
J19: Top Customers | K19: Basket Value | M19: ='Combined Pivot '!J5 -> Americano | N19: ='Combined Pivot '!K5 -> 12608.6 | O19: =index_1!E56 -> 28.9
J20: ='Combined Pivot '!D22 -> ANON-0000-0000-0012 | K20: ='Combined Pivot '!E22 -> 3143.74 | M20: ='Combined Pivot '!J6 -> Hot Chocolate | N20: ='Combined Pivot '!K6 -> 9135.42 | O20: =index_1!E49 -> 38.7
J21: ='Combined Pivot '!D23 -> ANON-0000-0000-0009 | K21: ='Combined Pivot '!E23 -> 2278.34 | M21: ='Combined Pivot '!J7 -> Cocoa | N21: ='Combined Pivot '!K7 -> 7576.46 | O21: =index_1!E38 -> 38.7
J22: ='Combined Pivot '!D24 -> ANON-0000-0000-0141 | K22: ='Combined Pivot '!E24 -> 2252.14 | M22: ='Combined Pivot '!J8 -> Cortado | N22: ='Combined Pivot '!K8 -> 6468.56 | O22: =index_1!E41 -> 28.9
J23: ='Combined Pivot '!D25 -> ANON-0000-0000-0276 | K23: ='Combined Pivot '!E25 -> 1930.46 | M23: ='Combined Pivot '!J9 -> Espresso | N23: ='Combined Pivot '!K9 -> 2699.68 | O23: =index_1!E33 -> 24
J24: ='Combined Pivot '!D26 -> ANON-0000-0000-1163 | K24: ='Combined Pivot '!E26 -> 1658.1
J25: ='Combined Pivot '!D27 -> ANON-0000-0000-0507 | K25: ='Combined Pivot '!E27 -> 1549.92
J26: ='Combined Pivot '!D28 -> ANON-0000-0000-0097 | K26: ='Combined Pivot '!E28 -> 1333.36
J27: ='Combined Pivot '!D29 -> ANON-0000-0000-0040 | K27: ='Combined Pivot '!E29 -> 1258.4
J28: ='Combined Pivot '!D30 -> ANON-0000-0000-0570 | K28: ='Combined Pivot '!E30 -> 1061.04

Sheet Pivot 2
A1: Row Labels | B1: Sum of money | D1: Row Labels | E1: Sum of money | G1: Day | H1: (All) | J1: Row Labels | K1: Sum of money
A2: Latte | B2: 27866.3 | D2: Tuesday | E2: 18637.38 | J2: card | K2: 112245.58
A3: Americano with Milk | B3: 25269.12 | D3: Monday | E3: 17925.1 | G3: Row Labels | H3: Sum of money | J3: cash | K3: 3186
A4: Cappuccino | B4: 18034.14 | D4: Friday | E4: 17257.66 | G4: Americano | H4: 15062.26 | J4: Grand Total | K4: 115431.58
A5: Americano | B5: 15062.26 | D5: Thursday | E5: 16477.4 | G5: Americano with Milk | H5: 25269.12
A6: Hot Chocolate | B6: 10172.46 | D6: Wednesday | E6: 16093.46 | G6: Cappuccino | H6: 18034.14
A7: Cocoa | B7: 8678.16 | D7: Saturday | E7: 15182.52 | G7: Cocoa | H7: 8678.16
A8: Cortado | B8: 7534.86 | D8: Sunday | E8: 13858.06 | G8: Cortado | H8: 7534.86
A9: Espresso | B9: 2814.28 | D9: Grand Total | E9: 115431.58 | G9: Espresso | H9: 2814.28
A10: Grand Total | B10: 115431.58 | G10: Hot Chocolate | H10: 10172.46
G11: Latte | H11: 27866.3
A12: Row Labels | B12: Sum of Total sales per Day | D12: Row Labels | E12: Sum of Total sales per Day | G12: Grand Total | H12: 115431.58
A13: January | B13: 6398.86 | D13: 2024 | E13: 85830.8
A14: April | B14: 6720.56 | D14: 2025 | E14: 29600.78
A15: July | B15: 6915.94 | D15: Grand Total | E15: 115431.58
A16: August | B16: 7613.84
A17: June | B17: 7758.76 | D17: Quarters | E17: Sales
A18: December | B18: 8237.74 | D18: 1 | E18: =SUM(GETPIVOTDATA("Total sales per Day",$A$12,"Month ","January"),GETPIVOTDATA("Total sales per Day",$A$12,"Month ","February"),GETPIVOTDATA("Total sales per Day",$A$12,"Month ","March")) -> 36650.98
A19: November | B19: 8590.54 | D19: 4 | E19: =SUM(GETPIVOTDATA("Total sales per Day",$A$12,"Month ","October"),GETPIVOTDATA("Total sales per Day",$A$12,"Month ","November"),GETPIVOTDATA("Total sales per Day",$A$12,"Month ","December")) -> 30719.44
A20: May | B20: 9063.42 | D20: 3 | E20: =SUM(GETPIVOTDATA("Total sales per Day",$A$12,"Month ","July"),GETPIVOTDATA("Total sales per Day",$A$12,"Month ","August"),GETPIVOTDATA("Total sales per Day",$A$12,"Month ","September")) -> 24518.42
A21: September | B21: 9988.64 | D21: 2 | E21: =SUM(GETPIVOTDATA("Total sales per Day",$A$12,"Month ","April"),GETPIVOTDATA("Total sales per Day",$A$12,"Month ","May"),GETPIVOTDATA("Total sales per Day",$A$12,"Month ","June")) -> 23542.74
A22: February | B22: 13215.48
A23: October | B23: 13891.16
A24: March | B24: 17036.64
A25: Grand Total | B25: 115431.58

Sheet Pivot
A3: Row Labels | B3: Sum of Sales | D3: Row Labels | E3: Sum of Sales | G3: Row Labels | H3: Sum of Sales | J3: Row Labels | K3: Sum of Price | L3: Sum of Sales percentage
A4: Tuesday | B4: 18637.38 | D4: March | E4: 17036.64 | G4: Espresso | H4: 2814.28 | J4: Latte | K4: 38.7 | L4: 0.24140967
A5: Monday | B5: 17925.1 | D5: October | E5: 13891.16 | G5: Cortado | H5: 7534.86 | J5: Americano with Milk | K5: 33.8 | L5: 0.21890994
A6: Friday | B6: 17257.66 | D6: February | E6: 13215.48 | G6: Cocoa | H6: 8678.16 | J6: Cappuccino | K6: 38.7 | L6: 0.15623229
A7: Thursday | B7: 16477.4 | D7: September | E7: 9988.64 | G7: Hot Chocolate | H7: 10172.46 | J7: Americano | K7: 28.9 | L7: 0.13048648
A8: Wednesday | B8: 16093.46 | D8: May | E8: 9063.42 | G8: Americano | H8: 15062.26 | J8: Hot Chocolate | K8: 38.7 | L8: 0.088125451
A9: Saturday | B9: 15182.52 | D9: November | E9: 8590.54 | G9: Cappuccino | H9: 18034.14 | J9: Cocoa | K9: 38.7 | L9: 0.07518012
A10: Sunday | B10: 13858.06 | D10: December | E10: 8237.74 | G10: Americano with Milk | H10: 25269.12 | J10: Cortado | K10: 28.9 | L10: 0.065275551
A11: Grand Total | B11: 115431.58 | D11: June | E11: 7758.76 | G11: Latte | H11: 27866.3 | J11: Espresso | K11: 24 | L11: 0.024380503
D12: August | E12: 7613.84 | G12: Grand Total | H12: 115431.58 | J12: Grand Total | K12: 270.4 | L12: 1
D13: July | E13: 6915.94
D14: April | E14: 6720.56
D15: January | E15: 6398.86
D16: Grand Total | E16: 115431.58 | K16: Row Labels | L16: Sum of Sales
A17: Row Labels | B17: Sum of SALES | D17: Row Labels | E17: Sum of Footfall | F17: Sum of Percentage | K17: 2024 | L17: 85830.8
A18: 4th | B18: 30719.44 | D18: Americano with Milk | E18: 824 | F18: 0.22662266 | K18: 2025 | L18: 29600.78
A19: 1st | B19: 28132.66 | D19: Latte | E19: 782 | F19: 0.21507151 | K19: Grand Total | L19: 115431.58
A20: 3rd | B20: 24518.42 | D20: Americano | E20: 578 | F20: 0.1589659
A21: 2nd | B21: 23542.74 | D21: Cappuccino | E21: 501 | F21: 0.13778878
A22: Grand Total | B22: 106913.26 | D22: Cortado | E22: 292 | F22: 0.080308031
D23: Hot Chocolate | E23: 282 | F23: 0.077557756
D24: Cocoa | E24: 243 | F24: 0.066831683
D25: Espresso | E25: 134 | F25: 0.036853685
D26: Grand Total | E26: 3636 | F26: 1

Sheet index_1
A1: date | B1: Day | C1: Cash_type | D1: card | E1: money | F1: coffee_name | G1: Date2 | H1: Total sales per Day | I1: Day of the Week | J1: Month | K1: Year | L1: Total Sales | M1: Average Sales | N1: Footfall
A2: 45352 | B2: =TEXT(A2,"dddd") -> Friday | C2: Card | D2: ANON-0000-0000-0001 | E2: 38.7 | F2: Latte | G2: =Table1[[#This Row],[date]] -> 45352 | H2: =SUMIF($A$2:A3231,G2,$E$2:E3231) -> 396.3 | I2: =TEXT(G2,"dddd") -> Friday | J2: =TEXT(G2,"mmmm") -> March | K2: =TEXT(G2,"yyyy") -> 2024 | L2: =SUM(E:E) -> 102955.92 | M2: =AVERAGE(E:E) -> 31.874898 | N2: =COUNT(A:A) -> 3230
A3: 45352 | B3: =TEXT(A3,"dddd") -> Friday | C3: Card | D3: ANON-0000-0000-0002 | E3: 38.7 | F3: Hot Chocolate | G3: =Table1[[#This Row],[date]] -> 45352 | H3: =SUMIF($A$2:A3638,G3,$E$2:E3638) -> 396.3 | I3: =TEXT(G3,"dddd") -> Friday | J3: =TEXT(G3,"mmmm") -> March | K3: =TEXT(G3,"yyyy") -> 2024
A4: 45352 | B4: =TEXT(A4,"dddd") -> Friday | C4: Card | D4: ANON-0000-0000-0002 | E4: 38.7 | F4: Hot Chocolate | G4: =Table1[[#This Row],[date]] -> 45352 | H4: =SUMIF($A$2:A3639,G4,$E$2:E3639) -> 396.3 | I4: =TEXT(G4,"dddd") -> Friday | J4: =TEXT(G4,"mmmm") -> March | K4: =TEXT(G4,"yyyy") -> 2024
A5: 45352 | B5: =TEXT(A5,"dddd") -> Friday | C5: Card | D5: ANON-0000-0000-0003 | E5: 28.9 | F5: Americano | G5: =Table1[[#This Row],[date]] -> 45352 | H5: =SUMIF($A$2:A3640,G5,$E$2:E3640) -> 396.3 | I5: =TEXT(G5,"dddd") -> Friday | J5: =TEXT(G5,"mmmm") -> March | K5: =TEXT(G5,"yyyy") -> 2024
A6: 45352 | B6: =TEXT(A6,"dddd") -> Friday | C6: Card | D6: ANON-0000-0000-0004 | E6: 38.7 | F6: Latte | G6: =Table1[[#This Row],[date]] -> 45352 | H6: =SUMIF($A$2:A3641,G6,$E$2:E3641) -> 396.3 | I6: =TEXT(G6,"dddd") -> Friday | J6: =TEXT(G6,"mmmm") -> March | K6: =TEXT(G6,"yyyy") -> 2024
A7: 45352 | B7: =TEXT(A7,"dddd") -> Friday | C7: Card | D7: ANON-0000-0000-0005 | E7: 33.8 | F7: Americano with Milk | G7: =Table1[[#This Row],[date]] -> 45352 | H7: =SUMIF($A$2:A3642,G7,$E$2:E3642) -> 396.3 | I7: =TEXT(G7,"dddd") -> Friday | J7: =TEXT(G7,"mmmm") -> March | K7: =TEXT(G7,"yyyy") -> 2024
A8: 45352 | B8: =TEXT(A8,"dddd") -> Friday | C8: Card | D8: ANON-0000-0000-0006 | E8: 38.7 | F8: Hot Chocolate | G8: =Table1[[#This Row],[date]] -> 45352 | H8: =SUMIF($A$2:A3643,G8,$E$2:E3643) -> 396.3 | I8: =TEXT(G8,"dddd") -> Friday | J8: =TEXT(G8,"mmmm") -> March | K8: =TEXT(G8,"yyyy") -> 2024
A9: 45352 | B9: =TEXT(A9,"dddd") -> Friday | C9: Card | D9: ANON-0000-0000-0007 | E9: 33.8 | F9: Americano with Milk | G9: =Table1[[#This Row],[date]] -> 45352 | H9: =SUMIF($A$2:A3644,G9,$E$2:E3644) -> 396.3 | I9: =TEXT(G9,"dddd") -> Friday | J9: =TEXT(G9,"mmmm") -> March | K9: =TEXT(G9,"yyyy") -> 2024
A10: 45352 | B10: =TEXT(A10,"dddd") -> Friday | C10: Card | D10: ANON-0000-0000-0008 | E10: 38.7 | F10: Cocoa | G10: =Table1[[#This Row],[date]] -> 45352 | H10: =SUMIF($A$2:A3645,G10,$E$2:E3645) -> 396.3 | I10: =TEXT(G10,"dddd") -> Friday | J10: =TEXT(G10,"mmmm") -> March | K10: =TEXT(G10,"yyyy") -> 2024
A11: 45352 | B11: =TEXT(A11,"dddd") -> Friday | C11: Card | D11: ANON-0000-0000-0008 | E11: 33.8 | F11: Americano with Milk | G11: =Table1[[#This Row],[date]] -> 45352 | H11: =SUMIF($A$2:A3646,G11,$E$2:E3646) -> 396.3 | I11: =TEXT(G11,"dddd") -> Friday | J11: =TEXT(G11,"mmmm") -> March | K11: =TEXT(G11,"yyyy") -> 2024
A12: 45352 | B12: =TEXT(A12,"dddd") -> Friday | C12: Card | D12: ANON-0000-0000-0009 | E12: 33.8 | F12: Americano with Milk | G12: =Table1[[#This Row],[date]] -> 45352 | H12: =SUMIF($A$2:A3647,G12,$E$2:E3647) -> 396.3 | I12: =TEXT(G12,"dddd") -> Friday | J12: =TEXT(G12,"mmmm") -> March | K12: =TEXT(G12,"yyyy") -> 2024
A13: 45353 | B13: =TEXT(A13,"dddd") -> Saturday | C13: Card | D13: ANON-0000-0000-0010 | E13: 28.9 | F13: Americano | G13: =Table1[[#This Row],[date]] -> 45353 | H13: =SUMIF($A$2:A3648,G13,$E$2:E3648) -> 228.1 | I13: =TEXT(G13,"dddd") -> Saturday | J13: =TEXT(G13,"mmmm") -> March | K13: =TEXT(G13,"yyyy") -> 2024
A14: 45353 | B14: =TEXT(A14,"dddd") -> Saturday | C14: Cash | E14: 40 | F14: Latte | G14: =Table1[[#This Row],[date]] -> 45353 | H14: =SUMIF($A$2:A3649,G14,$E$2:E3649) -> 228.1 | I14: =TEXT(G14,"dddd") -> Saturday | J14: =TEXT(G14,"mmmm") -> March | K14: =TEXT(G14,"yyyy") -> 2024
A15: 45353 | B15: =TEXT(A15,"dddd") -> Saturday | C15: Card | D15: ANON-0000-0000-0011 | E15: 33.8 | F15: Americano with Milk | G15: =Table1[[#This Row],[date]] -> 45353 | H15: =SUMIF($A$2:A3650,G15,$E$2:E3650) -> 228.1 | I15: =TEXT(G15,"dddd") -> Saturday | J15: =TEXT(G15,"mmmm") -> March | K15: =TEXT(G15,"yyyy") -> 2024
A16: 45353 | B16: =TEXT(A16,"dddd") -> Saturday | C16: Card | D16: ANON-0000-0000-0012 | E16: 33.8 | F16: Americano with Milk | G16: =Table1[[#This Row],[date]] -> 45353 | H16: =SUMIF($A$2:A3651,G16,$E$2:E3651) -> 228.1 | I16: =TEXT(G16,"dddd") -> Saturday | J16: =TEXT(G16,"mmmm") -> March | K16: =TEXT(G16,"yyyy") -> 2024
A17: 45353 | B17: =TEXT(A17,"dddd") -> Saturday | C17: Card | D17: ANON-0000-0000-0013 | E17: 28.9 | F17: Americano | G17: =Table1[[#This Row],[date]] -> 45353 | H17: =SUMIF($A$2:A3652,G17,$E$2:E3652) -> 228.1 | I17: =TEXT(G17,"dddd") -> Saturday | J17: =TEXT(G17,"mmmm") -> March | K17: =TEXT(G17,"yyyy") -> 2024
A18: 45353 | B18: =TEXT(A18,"dddd") -> Saturday | C18: Card | D18: ANON-0000-0000-0014 | E18: 33.8 | F18: Americano with Milk | G18: =Table1[[#This Row],[date]] -> 45353 | H18: =SUMIF($A$2:A3653,G18,$E$2:E3653) -> 228.1 | I18: =TEXT(G18,"dddd") -> Saturday | J18: =TEXT(G18,"mmmm") -> March | K18: =TEXT(G18,"yyyy") -> 2024
A19: 45353 | B19: =TEXT(A19,"dddd") -> Saturday | C19: Card | D19: ANON-0000-0000-0004 | E19: 28.9 | F19: Americano | G19: =Table1[[#This Row],[date]] -> 45353 | H19: =SUMIF($A$2:A3654,G19,$E$2:E3654) -> 228.1 | I19: =TEXT(G19,"dddd") -> Saturday | J19: =TEXT(G19,"mmmm") -> March | K19: =TEXT(G19,"yyyy") -> 2024
A20: 45354 | B20: =TEXT(A20,"dddd") -> Sunday | C20: Cash | E20: 40 | F20: Latte | G20: =Table1[[#This Row],[date]] -> 45354 | H20: =SUMIF($A$2:A3655,G20,$E$2:E3655) -> 349.1 | I20: =TEXT(G20,"dddd") -> Sunday | J20: =TEXT(G20,"mmmm") -> March | K20: =TEXT(G20,"yyyy") -> 2024
A21: 45354 | B21: =TEXT(A21,"dddd") -> Sunday | C21: Card | D21: ANON-0000-0000-0015 | E21: 38.7 | F21: Latte | G21: =Table1[[#This Row],[date]] -> 45354 | H21: =SUMIF($A$2:A3656,G21,$E$2:E3656) -> 349.1 | I21: =TEXT(G21,"dddd") -> Sunday | J21: =TEXT(G21,"mmmm") -> March | K21: =TEXT(G21,"yyyy") -> 2024
A22: 45354 | B22: =TEXT(A22,"dddd") -> Sunday | C22: Card | D22: ANON-0000-0000-0016 | E22: 28.9 | F22: Cortado | G22: =Table1[[#This Row],[date]] -> 45354 | H22: =SUMIF($A$2:A3657,G22,$E$2:E3657) -> 349.1 | I22: =TEXT(G22,"dddd") -> Sunday | J22: =TEXT(G22,"mmmm") -> March | K22: =TEXT(G22,"yyyy") -> 2024
A23: 45354 | B23: =TEXT(A23,"dddd") -> Sunday | C23: Card | D23: ANON-0000-0000-0012 | E23: 28.9 | F23: Americano | G23: =Table1[[#This Row],[date]] -> 45354 | H23: =SUMIF($A$2:A3658,G23,$E$2:E3658) -> 349.1 | I23: =TEXT(G23,"dddd") -> Sunday | J23: =TEXT(G23,"mmmm") -> March | K23: =TEXT(G23,"yyyy") -> 2024
A24: 45354 | B24: =TEXT(A24,"dddd") -> Sunday | C24: Card | D24: ANON-0000-0000-0017 | E24: 38.7 | F24: Hot Chocolate | G24: =Table1[[#This Row],[date]] -> 45354 | H24: =SUMIF($A$2:A3659,G24,$E$2:E3659) -> 349.1 | I24: =TEXT(G24,"dddd") -> Sunday | J24: =TEXT(G24,"mmmm") -> March | K24: =TEXT(G24,"yyyy") -> 2024
A25: 45354 | B25: =TEXT(A25,"dddd") -> Sunday | C25: Card | D25: ANON-0000-0000-0018 | E25: 38.7 | F25: Cocoa | G25: =Table1[[#This Row],[date]] -> 45354 | H25: =SUMIF($A$2:A3660,G25,$E$2:E3660) -> 349.1 | I25: =TEXT(G25,"dddd") -> Sunday | J25: =TEXT(G25,"mmmm") -> March | K25: =TEXT(G25,"yyyy") -> 2024
A26: 45354 | B26: =TEXT(A26,"dddd") -> Sunday | C26: Card | D26: ANON-0000-0000-0019 | E26: 28.9 | F26: Cortado | G26: =Table1[[#This Row],[date]] -> 45354 | H26: =SUMIF($A$2:A3661,G26,$E$2:E3661) -> 349.1 | I26: =TEXT(G26,"dddd") -> Sunday | J26: =TEXT(G26,"mmmm") -> March | K26: =TEXT(G26,"yyyy") -> 2024
A27: 45354 | B27: =TEXT(A27,"dddd") -> Sunday | C27: Card | D27: ANON-0000-0000-0020 | E27: 33.8 | F27: Americano with Milk | G27: =Table1[[#This Row],[date]] -> 45354 | H27: =SUMIF($A$2:A3662,G27,$E$2:E3662) -> 349.1 | I27: =TEXT(G27,"dddd") -> Sunday | J27: =TEXT(G27,"mmmm") -> March | K27: =TEXT(G27,"yyyy") -> 2024
A28: 45354 | B28: =TEXT(A28,"dddd") -> Sunday | C28: Card | D28: ANON-0000-0000-0020 | E28: 33.8 | F28: Americano with Milk | G28: =Table1[[#This Row],[date]] -> 45354 | H28: =SUMIF($A$2:A3663,G28,$E$2:E3663) -> 349.1 | I28: =TEXT(G28,"dddd") -> Sunday | J28: =TEXT(G28,"mmmm") -> March | K28: =TEXT(G28,"yyyy") -> 2024
A29: 45354 | B29: =TEXT(A29,"dddd") -> Sunday | C29: Card | D29: ANON-0000-0000-0020 | E29: 38.7 | F29: Hot Chocolate | G29: =Table1[[#This Row],[date]] -> 45354 | H29: =SUMIF($A$2:A3664,G29,$E$2:E3664) -> 349.1 | I29: =TEXT(G29,"dddd") -> Sunday | J29: =TEXT(G29,"mmmm") -> March | K29: =TEXT(G29,"yyyy") -> 2024
A30: 45355 | B30: =TEXT(A30,"dddd") -> Monday | C30: Card | D30: ANON-0000-0000-0001 | E30: 38.7 | F30: Latte | G30: =Table1[[#This Row],[date]] -> 45355 | H30: =SUMIF($A$2:A3665,G30,$E$2:E3665) -> 135.2 | I30: =TEXT(G30,"dddd") -> Monday | J30: =TEXT(G30,"mmmm") -> March | K30: =TEXT(G30,"yyyy") -> 2024
A31: 45355 | B31: =TEXT(A31,"dddd") -> Monday | C31: Card | D31: ANON-0000-0000-0021 | E31: 38.7 | F31: Latte | G31: =Table1[[#This Row],[date]] -> 45355 | H31: =SUMIF($A$2:A3666,G31,$E$2:E3666) -> 135.2 | I31: =TEXT(G31,"dddd") -> Monday | J31: =TEXT(G31,"mmmm") -> March | K31: =TEXT(G31,"yyyy") -> 2024
A32: 45355 | B32: =TEXT(A32,"dddd") -> Monday | C32: Card | D32: ANON-0000-0000-0012 | E32: 33.8 | F32: Americano with Milk | G32: =Table1[[#This Row],[date]] -> 45355 | H32: =SUMIF($A$2:A3667,G32,$E$2:E3667) -> 135.2 | I32: =TEXT(G32,"dddd") -> Monday | J32: =TEXT(G32,"mmmm") -> March | K32: =TEXT(G32,"yyyy") -> 2024
... A42: 45356 | B42: =TEXT(A42,"dddd") -> Tuesday | C42: Card | D42: ANON-0000-0000-0028 | E42: 38.7 | F42: Hot Chocolate | G42: =Table1[[#This Row],[date]] -> 45356 | H42: =SUMIF($A$2:A3677,G42,$E$2:E3677) -> 338.5 | I42: =TEXT(G42,"dddd") -> Tuesday | J42: =TEXT(G42,"mmmm") -> March | K42: =TEXT(G42,"yyyy") -> 2024
A43: 45357 | B43: =TEXT(A43,"dddd") -> Wednesday | C43: Cash | E43: 35 | F43: Americano with Milk | G43: =Table1[[#This Row],[date]] -> 45357 | H43: =SUMIF($A$2:A3678,G43,$E$2:E3678) -> 170.2 | I43: =TEXT(G43,"dddd") -> Wednesday | J43: =TEXT(G43,"mmmm") -> March | K43: =TEXT(G43,"yyyy") -> 2024
A44: 45357 | B44: =TEXT(A44,"dddd") -> Wednesday | C44: Card | D44: ANON-0000-0000-0012 | E44: 28.9 | F44: Americano | G44: =Table1[[#This Row],[date]] -> 45357 | H44: =SUMIF($A$2:A3679,G44,$E$2:E3679) -> 170.2 | I44: =TEXT(G44,"dddd") -> Wednesday | J44: =TEXT(G44,"mmmm") -> March | K44: =TEXT(G44,"yyyy") -> 2024
A45: 45357 | B45: =TEXT(A45,"dddd") -> Wednesday | C45: Card | D45: ANON-0000-0000-0012 | E45: 28.9 | F45: Cortado | G45: =Table1[[#This Row],[date]] -> 45357 | H45: =SUMIF($A$2:A3680,G45,$E$2:E3680) -> 170.2 | I45: =TEXT(G45,"dddd") -> Wednesday | J45: =TEXT(G45,"mmmm") -> March | K45: =TEXT(G45,"yyyy") -> 2024
A46: 45357 | B46: =TEXT(A46,"dddd") -> Wednesday | C46: Card | D46: ANON-0000-0000-0029 | E46: 38.7 | F46: Cappuccino | G46: =Table1[[#This Row],[date]] -> 45357 | H46: =SUMIF($A$2:A3681,G46,$E$2:E3681) -> 170.2 | I46: =TEXT(G46,"dddd") -> Wednesday | J46: =TEXT(G46,"mmmm") -> March | K46: =TEXT(G46,"yyyy") -> 2024
A47: 45357 | B47: =TEXT(A47,"dddd") -> Wednesday | C47: Card | D47: ANON-0000-0000-0029 | E47: 38.7 | F47: Cappuccino | G47: =Table1[[#This Row],[date]] -> 45357 | H47: =SUMIF($A$2:A3682,G47,$E$2:E3682) -> 170.2 | I47: =TEXT(G47,"dddd") -> Wednesday | J47: =TEXT(G47,"mmmm") -> March | K47: =TEXT(G47,"yyyy") -> 2024
A48: 45358 | B48: =TEXT(A48,"dddd") -> Thursday | C48: Cash | E48: 40 | F48: Latte | G48: =Table1[[#This Row],[date]] -> 45358 | H48: =SUMIF($A$2:A3683,G48,$E$2:E3683) -> 220.1 | I48: =TEXT(G48,"dddd") -> Thursday | J48: =TEXT(G48,"mmmm") -> March | K48: =TEXT(G48,"yyyy") -> 2024
A49: 45358 | B49: =TEXT(A49,"dddd") -> Thursday | C49: Card | D49: ANON-0000-0000-0030 | E49: 38.7 | F49: Hot Chocolate | G49: =Table1[[#This Row],[date]] -> 45358 | H49: =SUMIF($A$2:A3684,G49,$E$2:E3684) -> 220.1 | I49: =TEXT(G49,"dddd") -> Thursday | J49: =TEXT(G49,"mmmm") -> March | K49: =TEXT(G49,"yyyy") -> 2024
...
